<?xml version="1.0" encoding="utf-8"?>
<!-- This URDF was automatically created by SolidWorks to URDF Exporter! Originally created by Stephen Brawner (brawner@gmail.com) 
     Commit Version: 1.6.0-4-g7f85cfe  Build Version: 1.6.7995.38578
     For more information, please see http://wiki.ros.org/sw_urdf_exporter -->
<robot
  name="RobotScaraWithGripper">
  <link
    name="base_link">
    <inertial>
      <origin
        xyz="-0.15609 -0.0016863 0.25062"
        rpy="0 0 0" />
      <mass
        value="14.052" />
      <inertia
        ixx="0.56351"
        ixy="0.00030413"
        ixz="0.017757"
        iyy="0.56374"
        iyz="-0.0012972"
        izz="0.066772" />
    </inertial>
    <visual>
      <origin
        xyz="0 0 0"
        rpy="0 0 0" />
      <geometry>
        <mesh
          filename="package://RobotScaraWithGripper/meshes/base_link.STL" />
      </geometry>
      <material
        name="">
        <color
          rgba="0.89804 0.91765 0.92941 1" />
      </material>
    </visual>
    <collision>
      <origin
        xyz="0 0 0"
        rpy="0 0 0" />
      <geometry>
        <mesh
          filename="package://RobotScaraWithGripper/meshes/base_link.STL" />
      </geometry>
    </collision>
  </link>
  <link
    name="Link1">
    <inertial>
      <origin
        xyz="-0.056359 2.3516E-10 0"
        rpy="0 0 0" />
      <mass
        value="1.2027" />
      <inertia
        ixx="0.001609"
        ixy="1.8058E-11"
        ixz="0.00018904"
        iyy="0.0057321"
        iyz="6.1535E-12"
        izz="0.0067457" />
    </inertial>
    <visual>
      <origin
        xyz="0 0 0"
        rpy="0 0 0" />
      <geometry>
        <mesh
          filename="package://RobotScaraWithGripper/meshes/Link1.STL" />
      </geometry>
      <material
        name="">
        <color
          rgba="0.89804 0.91765 0.92941 1" />
      </material>
    </visual>
    <collision>
      <origin
        xyz="0 0 0"
        rpy="0 0 0" />
      <geometry>
        <mesh
          filename="package://RobotScaraWithGripper/meshes/Link1.STL" />
      </geometry>
    </collision>
  </link>
  <joint
    name="Joint1"
    type="prismatic">
    <origin
      xyz="0 0 0.30686"
      rpy="0 0 0" />
    <parent
      link="base_link" />
    <child
      link="Link1" />
    <axis
      xyz="0 0 -1" />
    <limit
      lower="0.15"
      upper="-0.15"
      effort="5"
      velocity="0.01" />
  </joint>
  <link
    name="Link2">
    <inertial>
      <origin
        xyz="0.22558 8.8601E-07 0.034559"
        rpy="0 0 0" />
      <mass
        value="1.3921" />
      <inertia
        ixx="0.0023969"
        ixy="1.4147E-07"
        ixz="-8.7167E-05"
        iyy="0.020922"
        iyz="6.8204E-09"
        izz="0.022324" />
    </inertial>
    <visual>
      <origin
        xyz="0 0 0"
        rpy="0 0 0" />
      <geometry>
        <mesh
          filename="package://RobotScaraWithGripper/meshes/Link2.STL" />
      </geometry>
      <material
        name="">
        <color
          rgba="0.89804 0.91765 0.92941 1" />
      </material>
    </visual>
    <collision>
      <origin
        xyz="0 0 0"
        rpy="0 0 0" />
      <geometry>
        <mesh
          filename="package://RobotScaraWithGripper/meshes/Link2.STL" />
      </geometry>
    </collision>
  </link>
  <joint
    name="Joint2"
    type="revolute">
    <origin
      xyz="0 0 0"
      rpy="0 0 0" />
    <parent
      link="Link1" />
    <child
      link="Link2" />
    <axis
      xyz="0 0 -1" />
    <limit
      lower="-2.87"
      upper="2.87"
      effort="0.5"
      velocity="0.01" />
  </joint>
  <link
    name="Link3">
    <inertial>
      <origin
        xyz="0.15992 -0.003251 0.031489"
        rpy="0 0 0" />
      <mass
        value="0.82346" />
      <inertia
        ixx="0.00097691"
        ixy="0.00011852"
        ixz="-5.1942E-07"
        iyy="0.006861"
        iyz="7.7427E-08"
        izz="0.0077311" />
    </inertial>
    <visual>
      <origin
        xyz="0 0 0"
        rpy="0 0 0" />
      <geometry>
        <mesh
          filename="package://RobotScaraWithGripper/meshes/Link3.STL" />
      </geometry>
      <material
        name="">
        <color
          rgba="0.89804 0.91765 0.92941 1" />
      </material>
    </visual>
    <collision>
      <origin
        xyz="0 0 0"
        rpy="0 0 0" />
      <geometry>
        <mesh
          filename="package://RobotScaraWithGripper/meshes/Link3.STL" />
      </geometry>
    </collision>
  </link>
  <joint
    name="Joint3"
    type="revolute">
    <origin
      xyz="0.325 0 0"
      rpy="0 0 0" />
    <parent
      link="Link2" />
    <child
      link="Link3" />
    <axis
      xyz="0 0 -1" />
    <limit
      lower="-3.1415"
      upper="3.1415"
      effort="0.5"
      velocity="0.01" />
  </joint>
  <link
    name="Link4">
    <inertial>
      <origin
        xyz="0.081298 -3.1739E-13 0.0031854"
        rpy="0 0 0" />
      <mass
        value="0.26408" />
      <inertia
        ixx="0.00013535"
        ixy="1.0514E-15"
        ixz="-6.7538E-06"
        iyy="0.0010714"
        iyz="2.6377E-17"
        izz="0.0012047" />
    </inertial>
    <visual>
      <origin
        xyz="0 0 0"
        rpy="0 0 0" />
      <geometry>
        <mesh
          filename="package://RobotScaraWithGripper/meshes/Link4.STL" />
      </geometry>
      <material
        name="">
        <color
          rgba="0.84706 0.84706 0.84706 1" />
      </material>
    </visual>
    <collision>
      <origin
        xyz="0 0 0"
        rpy="0 0 0" />
      <geometry>
        <mesh
          filename="package://RobotScaraWithGripper/meshes/Link4.STL" />
      </geometry>
    </collision>
  </link>
  <joint
    name="Joint4"
    type="revolute">
    <origin
      xyz="0.27494 -0.0055 0"
      rpy="0 0 0" />
    <parent
      link="Link3" />
    <child
      link="Link4" />
    <axis
      xyz="0 0 1" />
    <limit
      lower="-3.1415"
      upper="3.1415"
      effort="0.5"
      velocity="0.01" />
  </joint>
  <link
    name="gripper_base_link">
    <inertial>
      <origin
        xyz="0 0 0"
        rpy="0 0 0" />
      <mass
        value="0.0037324" />
      <inertia
        ixx="5.9097E-08"
        ixy="3.9728E-36"
        ixz="-7.5499E-24"
        iyy="5.9097E-08"
        iyz="-1.1452E-24"
        izz="5.5988E-08" />
    </inertial>
    <visual>
      <origin
        xyz="0 0 0"
        rpy="0 0 0" />
      <geometry>
        <mesh
          filename="package://RobotScaraWithGripper/meshes/gripper_base_link.STL" />
      </geometry>
      <material
        name="">
        <color
          rgba="1 0.94902 0.89804 1" />
      </material>
    </visual>
    <collision>
      <origin
        xyz="0 0 0"
        rpy="0 0 0" />
      <geometry>
        <mesh
          filename="package://RobotScaraWithGripper/meshes/gripper_base_link.STL" />
      </geometry>
    </collision>
  </link>
  <joint
    name="Joint5"
    type="fixed">
    <origin
      xyz="0.165 0 0.012"
      rpy="0 0 1.5708" />
    <parent
      link="Link4" />
    <child
      link="gripper_base_link" />
    <axis
      xyz="0 0 0" />
  </joint>
 
 <link
    name="gripper_pitch_link">
    <inertial>
      <origin
        xyz="-0.00983894571063188 -0.00352826915496522 0.0123556825487463"
        rpy="0 0 0" />
      <mass
        value="0.0409184168489891" />
      <inertia
        ixx="5.40954338049232E-06"
        ixy="1.36606087520665E-07"
        ixz="-7.01970060019843E-09"
        iyy="1.05805787497656E-05"
        iyz="1.45220691704708E-10"
        izz="1.28177523495093E-05" />
    </inertial>
    <visual>
      <origin
        xyz="0 0 0"
        rpy="0 0 0" />
      <geometry>
        <mesh
          filename="package://RobotScaraWithGripper/meshes/gripper_pitch_link.STL" />
      </geometry>
      <material
        name="">
        <color
          rgba="0.792156862745098 0.819607843137255 0.933333333333333 1" />
      </material>
    </visual>
    <collision>
      <origin
        xyz="0 0 0"
        rpy="0 0 0" />
      <geometry>
        <mesh
          filename="package://RobotScaraWithGripper/meshes/gripper_pitch_link.STL" />
      </geometry>
    </collision>
  </link>
  <joint
    name="GripperPitch"
    type="revolute">
    <origin
      xyz="0.00947499999999989 -0.0705000000000001 0.00999999999999999"
      rpy="1.57079632679491 0 0" />
    <parent
      link="gripper_base_link" />
    <child
      link="gripper_pitch_link" />
    <axis
      xyz="0 0 1" />
    <limit
      lower="-1.507"
      upper="1.507"
      effort="10"
      velocity="0.1" />
  </joint>
  <link
    name="gripper_base">
    <inertial>
      <origin
        xyz="5.16747092164926E-11 -3.42592151912971E-10 -0.0260183093277326"
        rpy="0 0 0" />
      <mass
        value="0.141117006524258" />
      <inertia
        ixx="4.25057513922627E-05"
        ixy="6.26711193622089E-14"
        ixz="1.24399989908209E-13"
        iyy="4.25057521933406E-05"
        iyz="-6.9717451505908E-14"
        izz="4.06101129946479E-05" />
    </inertial>
    <visual>
      <origin
        xyz="0 0 0"
        rpy="0 0 0" />
      <geometry>
        <mesh
          filename="package://RobotScaraWithGripper/meshes/gripper_base.STL" />
      </geometry>
      <material
        name="">
        <color
          rgba="0.792156862745098 0.819607843137255 0.933333333333333 1" />
      </material>
    </visual>
    <collision>
      <origin
        xyz="0 0 0"
        rpy="0 0 0" />
      <geometry>
        <mesh
          filename="package://RobotScaraWithGripper/meshes/gripper_base.STL" />
      </geometry>
    </collision>
  </link>
  <joint
    name="GripperYaw"
    type="revolute">
    <origin
      xyz="0 -0.0284999999999997 0.0140000000000001"
      rpy="1.57079632679491 0.523598775598298 -3.14159265358979" />
    <parent
      link="gripper_pitch_link" />
    <child
      link="gripper_base" />
    <axis
      xyz="0 0 -1" />
    <limit
      lower="-1.507"
      upper="1.507"
      effort="10"
      velocity="0.1" />
  </joint>
  <link
    name="G1">
    <inertial>
      <origin
        xyz="-0.00817463418487539 -0.000749619730026553 -0.036869107115067"
        rpy="0 0 0" />
      <mass
        value="0.00987886598007678" />
      <inertia
        ixx="2.44226344454493E-06"
        ixy="-6.56179534092328E-08"
        ixz="7.26249066264972E-07"
        iyy="3.95715478637953E-06"
        iyz="-3.78845430644684E-08"
        izz="2.01448096313555E-06" />
    </inertial>
    <visual>
      <origin
        xyz="0 0 0"
        rpy="0 0 0" />
      <geometry>
        <mesh
          filename="package://RobotScaraWithGripper/meshes/G1.STL" />
      </geometry>
      <material
        name="">
        <color
          rgba="0.501960784313725 0.501960784313725 1 1" />
      </material>
    </visual>
    <collision>
      <origin
        xyz="0 0 0"
        rpy="0 0 0" />
      <geometry>
        <mesh
          filename="package://RobotScaraWithGripper/meshes/G1.STL" />
      </geometry>
    </collision>
  </link>
  <joint
    name="GripperJoint1"
    type="revolute">
    <origin
      xyz="-0.0362777674951481 -0.00950160315817182 -0.0379249999961821"
      rpy="1.57079632679489 0 0" />
    <parent
      link="gripper_base" />
    <child
      link="G1" />
    <axis
      xyz="0.499999999999994 0 -0.866025403784442" />
    <limit
      lower="-1.7"
      upper="0"
      effort="10"
      velocity="0.1" />
  </joint>
  <link
    name="G2">
    <inertial>
      <origin
        xyz="-0.02551399442828 -0.000749619730027212 -0.0278422662840602"
        rpy="0 0 0" />
      <mass
        value="0.00987886598007678" />
      <inertia
        ixx="2.96426796505278E-06"
        ixy="-7.57690861289869E-08"
        ixz="1.77889285035265E-07"
        iyy="3.95715478637953E-06"
        iyz="-3.85763753128362E-22"
        izz="1.4924764426277E-06" />
    </inertial>
    <visual>
      <origin
        xyz="0 0 0"
        rpy="0 0 0" />
      <geometry>
        <mesh
          filename="package://RobotScaraWithGripper/meshes/G2.STL" />
      </geometry>
      <material
        name="">
        <color
          rgba="0.501960784313725 0.501960784313725 1 1" />
      </material>
    </visual>
    <collision>
      <origin
        xyz="0 0 0"
        rpy="0 0 0" />
      <geometry>
        <mesh
          filename="package://RobotScaraWithGripper/meshes/G2.STL" />
      </geometry>
    </collision>
  </link>
  <joint
    name="GripperJoint2"
    type="revolute">
    <origin
      xyz="0.0263675134592286 -0.0266666666642979 -0.0379249999961821"
      rpy="1.5707963267949 0 1.5707963267949" />
    <parent
      link="gripper_base" />
    <child
      link="G2" />
    <axis
      xyz="0 0 -1" />
    <limit
      lower="-1.7"
      upper="0"
      effort="10"
      velocity="0.1" />
  </joint>
  <link
    name="G3">
    <inertial>
      <origin
        xyz="-0.0255139944282799 -0.000749619730026935 -0.0278422662840602"
        rpy="0 0 0" />
      <mass
        value="0.00987886598007678" />
      <inertia
        ixx="2.96426796505279E-06"
        ixy="-7.57690861289889E-08"
        ixz="1.77889285035268E-07"
        iyy="3.95715478637953E-06"
        iyz="2.32441238522946E-20"
        izz="1.49247644262771E-06" />
    </inertial>
    <visual>
      <origin
        xyz="0 0 0"
        rpy="0 0 0" />
      <geometry>
        <mesh
          filename="package://RobotScaraWithGripper/meshes/G3.STL" />
      </geometry>
      <material
        name="">
        <color
          rgba="0.501960784313725 0.501960784313725 1 1" />
      </material>
    </visual>
    <collision>
      <origin
        xyz="0 0 0"
        rpy="0 0 0" />
      <geometry>
        <mesh
          filename="package://RobotScaraWithGripper/meshes/G3.STL" />
      </geometry>
    </collision>
  </link>
  <joint
    name="GripperJoint3"
    type="revolute">
    <origin
      xyz="0.0099102540359187 0.0361682698224692 -0.0379249999961821"
      rpy="1.57079632679489 0 -2.61799387799149" />
    <parent
      link="gripper_base" />
    <child
      link="G3" />
    <axis
      xyz="0 0 -1" />
    <limit
      lower="-1.7"
      upper="0"
      effort="10"
      velocity="0.1" />
  </joint>
</robot>